<?xml version="1.0"?>
<!--
 ~ Copyright 2019 The D'Suite Authors.
 ~
 ~ Licensed under the Apache License, Version 2.0 (the "License");
 ~ you may not use this file except in compliance with the License.
 ~ You may obtain a copy of the License at
 ~
 ~     http://www.apache.org/licenses/LICENSE-2.0
 ~
 ~ Unless required by applicable law or agreed to in writing, software
 ~ distributed under the License is distributed on an "AS IS" BASIS,
 ~ WITHOUT WARRANTIES OR CONDITIONS OF ANY KIND, either express or implied.
 ~ See the License for the specific language governing permissions and
 ~ limitations under the License.
 -->
<mujoco model="dkitty-v2">
  <compiler meshdir="./../../../dsuite-scenes/dkitty" texturedir="../../../dsuite-scenes/dkitty"/>
  <include file="./../../../dsuite-scenes/scenes/basic_scene.xml"/>
  <include file="./../../../dsuite-scenes/dkitty/assets/dependencies_xh-v2.xml"/>
  <asset>
    <hfield name="hf1" size="4.5 4.5 1 .1" nrow="120" ncol="120"/>
  </asset>
  <worldbody>
    <site name="target" pos="1 0 0" type="cylinder" size=".5 .005 0" rgba="0 1 0 1"/>
    <site name="heading" pos="1 0 0.25" type="cylinder" size=".05 .25 0" rgba="1 1 0 1"/>
    <geom name="hfield1" type="hfield" hfield="hf1" pos="0 0 -.005" material="MatPlane" rgba=".7 .7 .7 1"/>
    <geom name="obj1" pos="1 0 -.201" type="box" size=".020 1 .2"/>
    <body name="kitty_frame" pos="0 0 .350" euler="0 3.14 -1.57">
      <site name="torso" type="box" size=".090 .150 .007" pos="0 0 .01" euler="3.14 0 1.57" group="4"/>
      <geom type="sphere" size="0.010" mass="0.010" group="4"/>
      <camera name="trackingZ" pos="0 0 -3" zaxis="0 0 -3" mode="trackcom"/>
      <camera name="trackingY" pos="1.5 -1.5 0" xyaxes="-.7 -1 0 0 -.2 -1" mode="trackcom"/>
      <joint name="Tx" pos="0 0 0" axis="0 -1 0" limited="true" type="slide" range="-10 10"/>
      <joint name="Ty" pos="0 0 0" axis="-1 0 0" limited="true" type="slide" range="-10 10"/>
      <joint name="Tz" pos="0 0 0" axis="0 0 -1" limited="true" type="slide" range="-2 2"/>
      <joint name="Rx" pos="0 0 0" axis="0 -1 0" limited="true" range="-3.14 3.14"/>
      <joint name="Ry" pos="0 0 0" axis="-1 0 0" limited="true" range="-3.14 3.14"/>
      <joint name="Rz" pos="0 0 0" axis="0 0 -1" limited="true" range="-3.14 3.14"/>
      <include file="./../../../dsuite-scenes/dkitty/assets/chain_xh-v2.xml"/>
    </body>
  </worldbody>
</mujoco>
